[{"name": "test.test_triple_square.TripleSquare.test_calls", "status": "errored", "message": "<module 'src.triple_square' from '/Users/ciro/repos/Dat_Analy_UH/hy-data-analysis-with-python-2020/part01-e06_triple_square/src/triple_square.py'> does not have the attribute 'triple'", "passed": false, "points": ["p01-06.1"], "backtrace": ["  File \"/Users/ciro/anaconda3/lib/python3.7/unittest/case.py\", line 59, in testPartExecutor\n    yield\n", "  File \"/Users/ciro/anaconda3/lib/python3.7/unittest/case.py\", line 615, in run\n    testMethod()\n", "  File \"/Users/ciro/repos/Dat_Analy_UH/hy-data-analysis-with-python-2020/part01-e06_triple_square/test/test_triple_square.py\", line 63, in test_calls\n    self.call_helper([4, 10])\n", "  File \"/Users/ciro/repos/Dat_Analy_UH/hy-data-analysis-with-python-2020/part01-e06_triple_square/test/test_triple_square.py\", line 39, in call_helper\n    with patch(module_name+'.triple', side_effect=triple) as tr:\n", "  File \"/Users/ciro/anaconda3/lib/python3.7/unittest/mock.py\", line 1268, in __enter__\n    original, local = self.get_original()\n", "  File \"/Users/ciro/anaconda3/lib/python3.7/unittest/mock.py\", line 1242, in get_original\n    \"%s does not have the attribute %r\" % (target, name)\n"]}, {"name": "test.test_triple_square.TripleSquare.test_calls2", "status": "failed", "message": "10 not found in [3] : Wrong number of printed lines: 10!", "passed": false, "points": ["p01-06.2"], "backtrace": ["  File \"/Users/ciro/anaconda3/lib/python3.7/unittest/case.py\", line 59, in testPartExecutor\n    yield\n", "  File \"/Users/ciro/anaconda3/lib/python3.7/unittest/case.py\", line 615, in run\n    testMethod()\n", "  File \"/Users/ciro/repos/Dat_Analy_UH/hy-data-analysis-with-python-2020/part01-e06_triple_square/test/test_triple_square.py\", line 67, in test_calls2\n    self.content_helper([3])\n", "  File \"/Users/ciro/repos/Dat_Analy_UH/hy-data-analysis-with-python-2020/part01-e06_triple_square/test/test_triple_square.py\", line 23, in content_helper\n    self.assertIn(l, countlist, msg=\"Wrong number of printed lines: %i!\" % l)\n", "  File \"/Users/ciro/anaconda3/lib/python3.7/unittest/case.py\", line 1106, in assertIn\n    self.fail(self._formatMessage(msg, standardMsg))\n", "  File \"/Users/ciro/anaconda3/lib/python3.7/unittest/case.py\", line 680, in fail\n    raise self.failureException(msg)\n"]}, {"name": "test.test_triple_square.TripleSquare.test_square_output_and_type", "status": "failed", "message": "src.triple_square.square does not exist!", "passed": false, "points": ["p01-06.1"], "backtrace": ["  File \"/Users/ciro/anaconda3/lib/python3.7/unittest/case.py\", line 59, in testPartExecutor\n    yield\n", "  File \"/Users/ciro/anaconda3/lib/python3.7/unittest/case.py\", line 615, in run\n    testMethod()\n", "  File \"/Users/ciro/repos/Dat_Analy_UH/hy-data-analysis-with-python-2020/part01-e06_triple_square/test/test_triple_square.py\", line 56, in test_square_output_and_type\n    o = square(3)\n", "  File \"/Users/ciro/repos/Dat_Analy_UH/hy-data-analysis-with-python-2020/part01-e06_triple_square/tmc/utils.py\", line 11, in fail\n    raise AssertionError(err)\n"]}, {"name": "test.test_triple_square.TripleSquare.test_tiple_output_and_type", "status": "failed", "message": "src.triple_square.triple does not exist!", "passed": false, "points": ["p01-06.1"], "backtrace": ["  File \"/Users/ciro/anaconda3/lib/python3.7/unittest/case.py\", line 59, in testPartExecutor\n    yield\n", "  File \"/Users/ciro/anaconda3/lib/python3.7/unittest/case.py\", line 615, in run\n    testMethod()\n", "  File \"/Users/ciro/repos/Dat_Analy_UH/hy-data-analysis-with-python-2020/part01-e06_triple_square/test/test_triple_square.py\", line 50, in test_tiple_output_and_type\n    o = triple(6)\n", "  File \"/Users/ciro/repos/Dat_Analy_UH/hy-data-analysis-with-python-2020/part01-e06_triple_square/tmc/utils.py\", line 11, in fail\n    raise AssertionError(err)\n"]}]