[{"name": "test.test_merge.Merge.test_calls", "status": "failed", "message": "1 != 0 : You weren't allowed to use function 'sorted'!", "passed": false, "points": ["p01-09.1"], "backtrace": ["  File \"/Users/ciro/anaconda3/lib/python3.7/unittest/case.py\", line 59, in testPartExecutor\n    yield\n", "  File \"/Users/ciro/anaconda3/lib/python3.7/unittest/case.py\", line 615, in run\n    testMethod()\n", "  File \"/Users/ciro/repos/Data_Analysis_UHelsinki/hy-data-analysis-with-python-2020/part01-e09_merge/test/test_merge.py\", line 53, in test_calls\n    self.assertEqual(sorted.call_count, 0, msg=\"You weren't allowed to use function 'sorted'!\")\n", "  File \"/Users/ciro/anaconda3/lib/python3.7/unittest/case.py\", line 839, in assertEqual\n    assertion_func(first, second, msg=msg)\n", "  File \"/Users/ciro/anaconda3/lib/python3.7/unittest/case.py\", line 832, in _baseAssertEqual\n    raise self.failureException(msg)\n"]}, {"name": "test.test_merge.Merge.test_first", "status": "passed", "message": "", "passed": true, "points": ["p01-09.1"], "backtrace": []}, {"name": "test.test_merge.Merge.test_non_mutating", "status": "passed", "message": "", "passed": true, "points": ["p01-09.1"], "backtrace": []}, {"name": "test.test_merge.Merge.test_random", "status": "passed", "message": "", "passed": true, "points": ["p01-09.1"], "backtrace": []}]